<?xml version="1.0" ?>
<!-- =================================================================================== -->
<!-- |    This document was autogenerated by xacro from src/my_nav2_robot/urdf/robot.urdf.xacro | -->
<!-- |    EDITING THIS FILE BY HAND IS NOT RECOMMENDED                                 | -->
<!-- =================================================================================== -->
<robot name="my_nav2_bot">
  <!--声明材质颜色-->
  <material name="blue">
    <color rgba="0 0 1 1"/>
  </material>
  <material name="black">
    <color rgba="0 0 0 1"/>
  </material>
  <material name="red">
    <color rgba="1 0 0 1"/>
  </material>
  <!--机器人本体中心-->
  <link name="base_link">
    <visual>
      <origin rpy="0 0 0" xyz="0 0 0.05"/>
      <!--身体大小-->
      <geometry>
        <!--长方体-->
        <box size="0.4 0.3 0.1"/>
      </geometry>
      <material name="blue"/>
    </visual>
    <!--碰撞箱-->
    <collision>
      <origin rpy="0 0 0" xyz="0 0 0.05"/>
      <!--身体大小-->
      <geometry>
        <box size="0.4 0.3 0.1"/>
      </geometry>
    </collision>
    <inertial>
      <origin rpy="0 0 0" xyz="0 0 0.05"/>
      <mass value="5.0"/>
      <inertia ixx="0.041666666666666664" ixy="0.0" ixz="0.0" iyy="0.07083333333333335" iyz="0.0" izz="0.10416666666666666"/>
    </inertial>
  </link>
  <!--机器人中心在底面的投影-->
  <link name="base_footprint"/>
  <joint name="base_joint" type="fixed">
    <parent link="base_footprint"/>
    <child link="base_link"/>
    <origin rpy="0 0 0" xyz="0 0 0.07"/>
  </joint>
  <link name="front_left_wheel_link">
    <visual>
      <!--roll需要为pi/2的原因是圆柱体默认朝z轴向上-->
      <origin rpy="1.5707963267948966 0 0" xyz="0 0 0"/>
      <geometry>
        <!--圆柱体-->
        <cylinder length="0.04" radius="0.05"/>
      </geometry>
      <material name="black"/>
    </visual>
    <collision>
      <origin rpy="1.5707963267948966 0 0" xyz="0 0 0"/>
      <geometry>
        <cylinder length="0.04" radius="0.05"/>
      </geometry>
    </collision>
    <inertial>
      <origin rpy="1.5707963267948966 0 0" xyz="0 0 0"/>
      <mass value="0.5"/>
      <inertia ixx="0.00037916666666666676" ixy="0.0" ixz="0.0" iyy="0.00037916666666666676" iyz="0.0" izz="0.0006250000000000001"/>
    </inertial>
  </link>
  <joint name="front_left_wheel_joint" type="continuous">
    <parent link="base_link"/>
    <child link="front_left_wheel_link"/>
    <origin rpy="0 0 0" xyz="0.15000000000000002 0.16999999999999998 -0.02"/>
    <!--旋转轴-->
    <axis xyz="0 1 0"/>
  </joint>
  <link name="front_right_wheel_link">
    <visual>
      <!--roll需要为pi/2的原因是圆柱体默认朝z轴向上-->
      <origin rpy="1.5707963267948966 0 0" xyz="0 0 0"/>
      <geometry>
        <!--圆柱体-->
        <cylinder length="0.04" radius="0.05"/>
      </geometry>
      <material name="black"/>
    </visual>
    <collision>
      <origin rpy="1.5707963267948966 0 0" xyz="0 0 0"/>
      <geometry>
        <cylinder length="0.04" radius="0.05"/>
      </geometry>
    </collision>
    <inertial>
      <origin rpy="1.5707963267948966 0 0" xyz="0 0 0"/>
      <mass value="0.5"/>
      <inertia ixx="0.00037916666666666676" ixy="0.0" ixz="0.0" iyy="0.00037916666666666676" iyz="0.0" izz="0.0006250000000000001"/>
    </inertial>
  </link>
  <joint name="front_right_wheel_joint" type="continuous">
    <parent link="base_link"/>
    <child link="front_right_wheel_link"/>
    <origin rpy="0 0 0" xyz="0.15000000000000002 -0.16999999999999998 -0.02"/>
    <!--旋转轴-->
    <axis xyz="0 1 0"/>
  </joint>
  <link name="rear_left_wheel_link">
    <visual>
      <!--roll需要为pi/2的原因是圆柱体默认朝z轴向上-->
      <origin rpy="1.5707963267948966 0 0" xyz="0 0 0"/>
      <geometry>
        <!--圆柱体-->
        <cylinder length="0.04" radius="0.05"/>
      </geometry>
      <material name="black"/>
    </visual>
    <collision>
      <origin rpy="1.5707963267948966 0 0" xyz="0 0 0"/>
      <geometry>
        <cylinder length="0.04" radius="0.05"/>
      </geometry>
    </collision>
    <inertial>
      <origin rpy="1.5707963267948966 0 0" xyz="0 0 0"/>
      <mass value="0.5"/>
      <inertia ixx="0.00037916666666666676" ixy="0.0" ixz="0.0" iyy="0.00037916666666666676" iyz="0.0" izz="0.0006250000000000001"/>
    </inertial>
  </link>
  <joint name="rear_left_wheel_joint" type="continuous">
    <parent link="base_link"/>
    <child link="rear_left_wheel_link"/>
    <origin rpy="0 0 0" xyz="-0.15000000000000002 0.16999999999999998 -0.02"/>
    <!--旋转轴-->
    <axis xyz="0 1 0"/>
  </joint>
  <link name="rear_right_wheel_link">
    <visual>
      <!--roll需要为pi/2的原因是圆柱体默认朝z轴向上-->
      <origin rpy="1.5707963267948966 0 0" xyz="0 0 0"/>
      <geometry>
        <!--圆柱体-->
        <cylinder length="0.04" radius="0.05"/>
      </geometry>
      <material name="black"/>
    </visual>
    <collision>
      <origin rpy="1.5707963267948966 0 0" xyz="0 0 0"/>
      <geometry>
        <cylinder length="0.04" radius="0.05"/>
      </geometry>
    </collision>
    <inertial>
      <origin rpy="1.5707963267948966 0 0" xyz="0 0 0"/>
      <mass value="0.5"/>
      <inertia ixx="0.00037916666666666676" ixy="0.0" ixz="0.0" iyy="0.00037916666666666676" iyz="0.0" izz="0.0006250000000000001"/>
    </inertial>
  </link>
  <joint name="rear_right_wheel_joint" type="continuous">
    <parent link="base_link"/>
    <child link="rear_right_wheel_link"/>
    <origin rpy="0 0 0" xyz="-0.15000000000000002 -0.16999999999999998 -0.02"/>
    <!--旋转轴-->
    <axis xyz="0 1 0"/>
  </joint>
  <!--雷达-->
  <link name="laser_link">
    <visual>
      <geometry>
        <cylinder length="0.04" radius="0.03"/>
      </geometry>
      <material name="red"/>
    </visual>
    <inertial>
      <origin rpy="0 0 0" xyz="0 0 0"/>
      <mass value="0.1"/>
      <inertia ixx="3.5833333333333335e-05" ixy="0.0" ixz="0.0" iyy="3.5833333333333335e-05" iyz="0.0" izz="4.4999999999999996e-05"/>
    </inertial>
  </link>
  <joint name="laser_joint" type="fixed">
    <parent link="base_link"/>
    <child link="laser_link"/>
    <origin rpy="0 0 0" xyz="0 0 0.12000000000000001"/>
  </joint>
  <!--深度相机-->
  <!--物理位置-->
  <link name="camera_link">
    <visual>
      <geometry>
        <cylinder length="0.04" radius="0.03"/>
      </geometry>
      <material name="blue"/>
    </visual>
    <inertial>
      <origin rpy="0 0 0" xyz="0 0 0"/>
      <mass value="0.1"/>
      <inertia ixx="3.5833333333333335e-05" ixy="0.0" ixz="0.0" iyy="3.5833333333333335e-05" iyz="0.0" izz="4.4999999999999996e-05"/>
    </inertial>
  </link>
  <joint name="camera_joint" type="fixed">
    <parent link="base_link"/>
    <child link="camera_link"/>
    <origin rpy="0 0 0" xyz="0.2 0 0.06000000000000001"/>
  </joint>
  <!--雷达插件-->
  <gazebo reference="laser_link">
    <sensor name="gpu_lidar" type="gpu_lidar">
      <topic>scan</topic>
      <pose>0 0 0 0 0 0</pose>
      <frame_id>laser_link</frame_id>
      <gz_frame_id>laser_link</gz_frame_id>
      <visualize>true</visualize>
      <update_rate>50</update_rate>
      <lidar>
        <scan>
          <horizontal>
            <samples>360</samples>
            <resolution>1</resolution>
            <min_angle>-3.14159</min_angle>
            <max_angle>3.14159</max_angle>
          </horizontal>
        </scan>
        <range>
          <min>0.12</min>
          <max>12.0</max>
          <resolution>0.01</resolution>
        </range>
      </lidar>
    </sensor>
  </gazebo>
  <!--深度相机插件-->
  <gazebo reference="camera_link">
    <sensor name="depth_camera" type="rgbd_camera">
      <visualize>true</visualize>
      <update_rate>10.0</update_rate>
      <topic>depth_camera</topic>
      <gz_frame_id>camera_link</gz_frame_id>
      <camera>
        <horizontal_fov>1.047198</horizontal_fov>
        <image>
          <width>640</width>
          <height>480</height>
          <format>R8G8B8</format>
        </image>
        <clip>
          <near>0.1</near>
          <far>5.0</far>
        </clip>
      </camera>
    </sensor>
  </gazebo>
  <!--全局挂载插件-->
  <gazebo>
    <plugin filename="gz-sim-sensors-system" name="gz::sim::systems::Sensors">
      <render_engine>ogre2</render_engine>
    </plugin>
  </gazebo>
  <gazebo reference="front_left_wheel_link">
    <mu1>0.5</mu1>
    <mu2>0.5</mu2>
  </gazebo>
  <gazebo reference="front_right_wheel_link">
    <mu1>0.5</mu1>
    <mu2>0.5</mu2>
  </gazebo>
  <gazebo reference="rear_left_wheel_link">
    <mu1>0.5</mu1>
    <mu2>0.5</mu2>
  </gazebo>
  <gazebo reference="rear_right_wheel_link">
    <mu1>0.5</mu1>
    <mu2>0.5</mu2>
  </gazebo>
  <gazebo>
    <plugin filename="gz-sim-diff-drive-system" name="gz::sim::systems::DiffDrive">
      <left_joint>front_left_wheel_joint</left_joint>
      <right_joint>front_right_wheel_joint</right_joint>
      <left_joint>rear_left_wheel_joint</left_joint>
      <right_joint>rear_right_wheel_joint</right_joint>
      <wheel_separation>0.33999999999999997</wheel_separation>
      <wheel_radius>0.05</wheel_radius>
      <max_wheel_torque>20</max_wheel_torque>
      <max_wheel_acceleration>3.5</max_wheel_acceleration>
      <topic>cmd_vel</topic>
      <odom_topic>odom</odom_topic>
      <tf_topic>/tf</tf_topic>
      <!--重要-->
      <frame_id>odom</frame_id>
      <child_frame_id>base_footprint</child_frame_id>
      <publish_odom>true</publish_odom>
      <publish_odom_tf>false</publish_odom_tf>
      <publish_wheel_tf>true</publish_wheel_tf>
      <odometry_frame>odom</odometry_frame>
      <use_gz_time>true</use_gz_time>
    </plugin>
    <plugin filename="gz-sim-joint-state-publisher-system" name="gz::sim::systems::JointStatePublisher">
      <topic>joint_states</topic>
    </plugin>
  </gazebo>
  <gazebo>
    <plugin filename="gz-sim-odometry-publisher-system" name="gz::sim::systems::OdometryPublisher">
      <odom_topic>ground_truth</odom_topic>
      <odom_frame>world</odom_frame>
      <robot_base_frame>base_footprint</robot_base_frame>
      <tf_topic>ground_truth/tf</tf_topic>
      <dimensions>3</dimensions>
    </plugin>
  </gazebo>
</robot>
